Workbook

Sheet Factor list
A1: S.No. | B1: Factors | C1: SF# | D1: Sub-factors | E1: Intent | F1: Questions
A2: 1 | B2: Physiological factors | C2: 1.1 | D2: DoB | F2: 1
C3: 1.2 | D3: Life stage | F3: 1
C4: 1.3 | D4: Gender | F4: 1
C5: 1.4 | D5: Body composition | F5: 1
C6: 1.5 | D6: Genetics | F6: 1
C7: 1.6 | D7: Metabolic rate and recovery | F7: 1
A8: 2 | B8: Psychological factors | C8: 2.1 | D8: Motivation type | F8: 3
C9: 2.2 | D9: Mindset | F9: 3
C10: 2.3 | D10: Discipline | F10: 3
C11: 2.4 | D11: Self-efficacy | F11: 3
C12: 2.5 | D12: Personality traits | F12: 3
C13: 2.6 | D13: Emotional health & stress resilience | F13: 3
A14: 3 | B14: Behavioral factors | C14: 3.1 | D14: Daily habits & routines | F14: 3
C15: 3.2 | D15: Past behaviour patterns | F15: 3
C16: 3.3 | D16: Sleep hygiene | F16: 3
C17: 3.4 | D17: Substance use | F17: 3
C18: 3.5 | D18: Consistency & adaptability | F18: 3
A19: 4 | B19: Knowledge & awareness | C19: 4.1 | D19: Health literacy | F19: 3
C20: 4.2 | D20: Nutrition knowledge | F20: 3
C21: 4.3 | D21: Exercise knowledge | F21: 3
C22: 4.4 | D22: Awareness of long-term benefits | F22: 3
C23: 4.5 | D23: Susceptibility to misinformation | F23: 3
A24: 5 | B24: Sociocultural factors | C24: 5.1 | D24: Social support system | F24: 3
C25: 5.2 | D25: Cultural norms | F25: 3
C26: 5.3 | D26: Religious/spiritual beliefs | F26: 3
C27: 5.4 | D27: Community & Peer behaviour | F27: 3
C28: 5.5 | D28: Socioeconomic status | F28: 3
C29: 5.6 | D29: Living environment | F29: 3
A30: 6 | B30: Technological engagement factors | C30: 6.1 | D30: Use of fitness apps | F30: 3
C31: 6.2 | D31: Wearble tech adoption | F31: 3
C32: 6.3 | D32: Engagement in online communities | F32: 3
C33: 6.4 | D33: Exposure to social media influencers | F33: 3
C34: 6.5 | D34: Digital health literacy | F34: 3
A35: 7 | B35: Occupational and lifestyle factors | C35: 7.1 | D35: Job activity level | F35: 3
C36: 7.2 | D36: Work hours & flexibility | F36: 3
C37: 7.3 | D37: workplace wellness culture | F37: 3
C38: 7.4 | D38: occupational stress & demands | F38: 3
F39: =SUM(F2:F38) -> 99

Sheet Questionnaire
A1: S.No. | B1: Category | C1: Question ID | D1: Revised Question | E1: Direct / Reverse Keyed
A2: 1 | B2: Nutritional Curiosity | C2: O-NC-1 | D2: I enjoy trying foods that I have never eaten before. | E2: Direct
A3: 2 | B3: Nutritional Curiosity | C3: O-NC-2 | D3: I am interested in trying healthy foods that are new to me, even if they are unfamiliar. | E3: Direct
A4: 3 | B4: Nutritional Curiosity | C4: O-NC-3 | D4: I usually prefer familiar foods instead of trying different ones. | E4: Reverse
A5: 4 | B5: Exercise Exploration | C5: O-EE-1 | D5: I am willing to try a new type of physical activity if it looks interesting. | E5: Direct
A6: 5 | B6: Exercise Exploration | C6: O-EE-2 | D6: I enjoy learning about different ways people stay physically active. | E6: Direct
A7: 6 | B7: Exercise Exploration | C7: O-EE-3 | D7: I prefer sticking to activities I already know rather than trying new ones. | E7: Reverse
A8: 7 | B8: Recovery Exploration | C8: O-RE-1 | D8: I am curious about different ways people recover and recharge their bodies. | E8: Direct
A9: 8 | B9: Recovery Exploration | C9: O-RE-2 | D9: I like learning about methods that may help people feel refreshed and recovered. | E9: Direct
A10: 9 | B10: Recovery Exploration | C10: O-RE-3 | D10: I usually rely on the same recovery habits and rarely explore alternatives. | E10: Reverse
A11: 10 | B11: Mind-Body Exploration | C11: O-ME-1 | D11: I am interested in activities that help me understand my thoughts and feelings better. | E11: Direct
A12: 11 | B12: Mind-Body Exploration | C12: O-ME-2 | D12: I'm curious about practices like breathing exercises or meditation that help calm the mind. | E12: Direct
A13: 12 | B13: Mind-Body Exploration | C13: O-ME-3 | D13: I don't usually spend time thinking about how my mood or stress levels affect my health. | E13: Reverse
... A91: 90 | B91: Emotional Recovery Resilience | C91: N-ER-3 | D91: After a bad day, I usually bounce back and get going again without much trouble. | E91: Reverse

Sheet Assessment Engine
A1: S.No. | B1: Traits | C1: Facet ID | D1: Facet | E1: Q.ID | F1: Option A | G1: Option B | H1: Option C | I1: Option D | J1: Option E | K1: Option F | L1: Option G | M1: Response | N1: Facet Avg | O1: Trait Avg | P1: Steady Elephant | Q1: Pack Wolf | R1: Watchful Deer | S1: Curious Fox | T1: Steadfast Bear | U1: Shielded Turtle
A2: 1 | B2: Openness | C2: =LEFT(E2,4) -> O-NC | D2: Nutritional Curiosity | E2: O-NC-1 | F2: 1 | G2: 2 | H2: 3 | I2: 4 | J2: 5 | K2: 6 | L2: 7 | M2: 4 | N2: =AVERAGE(M2:M4) -> 3.3333333 | O2: =AVERAGE(M2:M19) -> 3.3333333 | P2: =($O$2-Centroids!F3)^2 -> 0.027777778 | Q2: =($O$2-Centroids!G3)^2 -> 1.3611111 | R2: =($O$2-Centroids!H3)^2 -> 1.3611111 | S2: =($O$2-Centroids!I3)^2 -> 10.027778 | T2: =($O$2-Centroids!J3)^2 -> 0.11111111 | U2: =($O$2-Centroids!K3)^2 -> 0.69444444
A3: 2 | B3: Openness | C3: =LEFT(E3,4) -> O-NC | D3: Nutritional Curiosity | E3: O-NC-2 | F3: 1 | G3: 2 | H3: 3 | I3: 4 | J3: 5 | K3: 6 | L3: 7 | M3: 4
A4: 3 | B4: Openness | C4: =LEFT(E4,4) -> O-NC | D4: Nutritional Curiosity | E4: O-NC-3 | F4: 1 | G4: 2 | H4: 3 | I4: 4 | J4: 5 | K4: 6 | L4: 7 | M4: 2
A5: 4 | B5: Openness | C5: =LEFT(E5,4) -> O-EE | D5: Exercise Exploration | E5: O-EE-1 | F5: 1 | G5: 2 | H5: 3 | I5: 4 | J5: 5 | K5: 6 | L5: 7 | M5: 4 | N5: =AVERAGE(M5:M7) -> 3.3333333
A6: 5 | B6: Openness | C6: =LEFT(E6,4) -> O-EE | D6: Exercise Exploration | E6: O-EE-2 | F6: 1 | G6: 2 | H6: 3 | I6: 4 | J6: 5 | K6: 6 | L6: 7 | M6: 4
A7: 6 | B7: Openness | C7: =LEFT(E7,4) -> O-EE | D7: Exercise Exploration | E7: O-EE-3 | F7: 1 | G7: 2 | H7: 3 | I7: 4 | J7: 5 | K7: 6 | L7: 7 | M7: 2
A8: 7 | B8: Openness | C8: =LEFT(E8,4) -> O-RE | D8: Recovery Exploration | E8: O-RE-1 | F8: 1 | G8: 2 | H8: 3 | I8: 4 | J8: 5 | K8: 6 | L8: 7 | M8: 4 | N8: =AVERAGE(M8:M10) -> 3.3333333
A9: 8 | B9: Openness | C9: =LEFT(E9,4) -> O-RE | D9: Recovery Exploration | E9: O-RE-2 | F9: 1 | G9: 2 | H9: 3 | I9: 4 | J9: 5 | K9: 6 | L9: 7 | M9: 4
A10: 9 | B10: Openness | C10: =LEFT(E10,4) -> O-RE | D10: Recovery Exploration | E10: O-RE-3 | F10: 1 | G10: 2 | H10: 3 | I10: 4 | J10: 5 | K10: 6 | L10: 7 | M10: 2
A11: 10 | B11: Openness | C11: =LEFT(E11,4) -> O-ME | D11: Mind-Body Exploration | E11: O-ME-1 | F11: 1 | G11: 2 | H11: 3 | I11: 4 | J11: 5 | K11: 6 | L11: 7 | M11: 4 | N11: =AVERAGE(M11:M13) -> 3.3333333
A12: 11 | B12: Openness | C12: =LEFT(E12,4) -> O-ME | D12: Mind-Body Exploration | E12: O-ME-2 | F12: 1 | G12: 2 | H12: 3 | I12: 4 | J12: 5 | K12: 6 | L12: 7 | M12: 4
A13: 12 | B13: Openness | C13: =LEFT(E13,4) -> O-ME | D13: Mind-Body Exploration | E13: O-ME-3 | F13: 1 | G13: 2 | H13: 3 | I13: 4 | J13: 5 | K13: 6 | L13: 7 | M13: 2
A14: 13 | B14: Openness | C14: =LEFT(E14,4) -> O-WL | D14: Wellness Learning Orientation | E14: O-WL-1 | F14: 1 | G14: 2 | H14: 3 | I14: 4 | J14: 5 | K14: 6 | L14: 7 | M14: 4 | N14: =AVERAGE(M14:M16) -> 3.3333333
A15: 14 | B15: Openness | C15: =LEFT(E15,4) -> O-WL | D15: Wellness Learning Orientation | E15: O-WL-2 | F15: 1 | G15: 2 | H15: 3 | I15: 4 | J15: 5 | K15: 6 | L15: 7 | M15: 4
A16: 15 | B16: Openness | C16: =LEFT(E16,4) -> O-WL | D16: Wellness Learning Orientation | E16: O-WL-3 | F16: 1 | G16: 2 | H16: 3 | I16: 4 | J16: 5 | K16: 6 | L16: 7 | M16: 2
A17: 16 | B17: Openness | C17: =LEFT(E17,4) -> O-WA | D17: Wellness Adaptability | E17: O-WA-1 | F17: 1 | G17: 2 | H17: 3 | I17: 4 | J17: 5 | K17: 6 | L17: 7 | M17: 4 | N17: =AVERAGE(M17:M19) -> 3.3333333
A18: 17 | B18: Openness | C18: =LEFT(E18,4) -> O-WA | D18: Wellness Adaptability | E18: O-WA-2 | F18: 1 | G18: 2 | H18: 3 | I18: 4 | J18: 5 | K18: 6 | L18: 7 | M18: 4
A19: 18 | B19: Openness | C19: =LEFT(E19,4) -> O-WA | D19: Wellness Adaptability | E19: O-WA-3 | F19: 1 | G19: 2 | H19: 3 | I19: 4 | J19: 5 | K19: 6 | L19: 7 | M19: 2
A20: 19 | B20: Conscientiousness | C20: =LEFT(E20,4) -> C-MP | D20: Meal Planning Discipline | E20: C-MP-1 | F20: 1 | G20: 2 | H20: 3 | I20: 4 | J20: 5 | K20: 6 | L20: 7 | M20: 6 | N20: =AVERAGE(M20:M22) -> 4.6666667 | O20: =AVERAGE(N20:N35) -> 4.6666667 | P20: =($O$20-Centroids!F4)^2 -> 3.3611111 | Q20: =($O$20-Centroids!G4)^2 -> 0.28444444 | R20: =($O$20-Centroids!H4)^2 -> 3.4844444 | S20: =($O$20-Centroids!I4)^2 -> 4.6944444 | T20: =($O$20-Centroids!J4)^2 -> 1.2844444 | U20: =($O$20-Centroids!K4)^2 -> 4.6944444
A21: 20 | B21: Conscientiousness | C21: =LEFT(E21,4) -> C-MP | D21: Meal Planning Discipline | E21: C-MP-2 | F21: 1 | G21: 2 | H21: 3 | I21: 4 | J21: 5 | K21: 6 | L21: 7 | M21: 7
A22: 21 | B22: Conscientiousness | C22: =LEFT(E22,4) -> C-MP | D22: Meal Planning Discipline | E22: C-MP-3 | F22: 1 | G22: 2 | H22: 3 | I22: 4 | J22: 5 | K22: 6 | L22: 7 | M22: 1
A23: 22 | B23: Conscientiousness | C23: =LEFT(E23,4) -> C-WA | D23: Workout Adherence | E23: C-WA-1 | F23: 1 | G23: 2 | H23: 3 | I23: 4 | J23: 5 | K23: 6 | L23: 7 | M23: 6 | N23: =AVERAGE(M23:M25) -> 4.6666667
A24: 23 | B24: Conscientiousness | C24: =LEFT(E24,4) -> C-WA | D24: Workout Adherence | E24: C-WA-2 | F24: 1 | G24: 2 | H24: 3 | I24: 4 | J24: 5 | K24: 6 | L24: 7 | M24: 7
A25: 24 | B25: Conscientiousness | C25: =LEFT(E25,4) -> C-WA | D25: Workout Adherence | E25: C-WA-3 | F25: 1 | G25: 2 | H25: 3 | I25: 4 | J25: 5 | K25: 6 | L25: 7 | M25: 1
A26: 25 | B26: Conscientiousness | C26: =LEFT(E26,4) -> C-SR | D26: Sleep Routine Consistency | E26: C-SR-1 | F26: 1 | G26: 2 | H26: 3 | I26: 4 | J26: 5 | K26: 6 | L26: 7 | M26: 6 | N26: =AVERAGE(M26:M28) -> 4.6666667
A27: 26 | B27: Conscientiousness | C27: =LEFT(E27,4) -> C-SR | D27: Sleep Routine Consistency | E27: C-SR-2 | F27: 1 | G27: 2 | H27: 3 | I27: 4 | J27: 5 | K27: 6 | L27: 7 | M27: 7
A28: 27 | B28: Conscientiousness | C28: =LEFT(E28,4) -> C-SR | D28: Sleep Routine Consistency | E28: C-SR-3 | F28: 1 | G28: 2 | H28: 3 | I28: 4 | J28: 5 | K28: 6 | L28: 7 | M28: 1
A29: 28 | B29: Conscientiousness | C29: =LEFT(E29,4) -> C-PT | D29: Progress Tracking | E29: C-PT-1 | F29: 1 | G29: 2 | H29: 3 | I29: 4 | J29: 5 | K29: 6 | L29: 7 | M29: 6 | N29: =AVERAGE(M29:M31) -> 4.6666667
A30: 29 | B30: Conscientiousness | C30: =LEFT(E30,4) -> C-PT | D30: Progress Tracking | E30: C-PT-2 | F30: 1 | G30: 2 | H30: 3 | I30: 4 | J30: 5 | K30: 6 | L30: 7 | M30: 7
A31: 30 | B31: Conscientiousness | C31: =LEFT(E31,4) -> C-PT | D31: Progress Tracking | E31: C-PT-3 | F31: 1 | G31: 2 | H31: 3 | I31: 4 | J31: 5 | K31: 6 | L31: 7 | M31: 1
A32: 31 | B32: Conscientiousness | C32: =LEFT(E32,4) -> C-IC | D32: Impulse Control | E32: C-IC-1 | F32: 1 | G32: 2 | H32: 3 | I32: 4 | J32: 5 | K32: 6 | L32: 7 | M32: 6 | N32: =AVERAGE(M32:M34) -> 4.6666667
A33: 32 | B33: Conscientiousness | C33: =LEFT(E33,4) -> C-IC | D33: Impulse Control | E33: C-IC-2 | F33: 1 | G33: 2 | H33: 3 | I33: 4 | J33: 5 | K33: 6 | L33: 7 | M33: 7
A34: 33 | B34: Conscientiousness | C34: =LEFT(E34,4) -> C-IC | D34: Impulse Control | E34: C-IC-3 | F34: 1 | G34: 2 | H34: 3 | I34: 4 | J34: 5 | K34: 6 | L34: 7 | M34: 1
A35: 34 | B35: Conscientiousness | C35: =LEFT(E35,4) -> C-RD | D35: Recovery Discipline | E35: C-RD-1 | F35: 1 | G35: 2 | H35: 3 | I35: 4 | J35: 5 | K35: 6 | L35: 7 | M35: 6 | N35: =AVERAGE(M35:M37) -> 4.6666667
A36: 35 | B36: Conscientiousness | C36: =LEFT(E36,4) -> C-RD | D36: Recovery Discipline | E36: C-RD-2 | F36: 1 | G36: 2 | H36: 3 | I36: 4 | J36: 5 | K36: 6 | L36: 7 | M36: 7
A37: 36 | B37: Conscientiousness | C37: =LEFT(E37,4) -> C-RD | D37: Recovery Discipline | E37: C-RD-3 | F37: 1 | G37: 2 | H37: 3 | I37: 4 | J37: 5 | K37: 6 | L37: 7 | M37: 1
A38: 37 | B38: Extraversion | C38: =LEFT(E38,4) -> E-SW | D38: Social Workout Preference | E38: E-SW-1 | F38: 1 | G38: 2 | H38: 3 | I38: 4 | J38: 5 | K38: 6 | L38: 7 | M38: 4 | N38: =AVERAGE(M38:M40) -> 3.6666667 | O38: =AVERAGE(N38:N53) -> 3.6666667 | P38: =($O$38-Centroids!F5)^2 -> 0.87111111 | Q38: =($O$38-Centroids!G5)^2 -> 8.0277778 | R38: =($O$38-Centroids!H5)^2 -> 0.75111111 | S38: =($O$38-Centroids!I5)^2 -> 3.3611111 | T38: =($O$38-Centroids!J5)^2 -> 0.44444444 | U38: =($O$38-Centroids!K5)^2 -> 2.7777778
A39: 38 | B39: Extraversion | C39: =LEFT(E39,4) -> E-SW | D39: Social Workout Preference | E39: E-SW-2 | F39: 1 | G39: 2 | H39: 3 | I39: 4 | J39: 5 | K39: 6 | L39: 7 | M39: 5
A40: 39 | B40: Extraversion | C40: =LEFT(E40,4) -> E-SW | D40: Social Workout Preference | E40: E-SW-3 | F40: 1 | G40: 2 | H40: 3 | I40: 4 | J40: 5 | K40: 6 | L40: 7 | M40: 2
...

Sheet Centroids
C1: Weights | F1: Benchmark Centroids | L1: Weighted Centroids
A2: S.No. | B2: Factors | C2: Base w | D2: Context tweak | E2: Final w | F2: Steady Elephant | G2: Pack Wolf | H2: Watchful Deer | I2: Curious Fox | J2: Steadfast Bear | K2: Shielded Turtle | L2: Steady Elephant | M2: Pack Wolf | N2: Watchful Deer | O2: Curious Fox | P2: Steadfast Bear | Q2: Shielded Turtle
A3: 1 | B3: Openness | C3: 1 | D3: 0 | E3: =C3*(1+D3) -> 1 | F3: 3.5 | G3: 4.5 | H3: 4.5 | I3: 6.5 | J3: 3 | K3: 2.5 | L3: =$E$5*F3 -> 3.5 | M3: =$E$4*G3 -> 4.5 | N3: =$E$4*H3 -> 4.5 | O3: =$E$6*I3 -> 6.5 | P3: =$E$6*J3 -> 3 | Q3: =$E$4*K3 -> 2.5
A4: 2 | B4: Conscientousness | C4: 1 | D4: 0 | E4: =C4*(1+D4) -> 1 | F4: 6.5 | G4: 5.2 | H4: 2.8 | I4: 2.5 | J4: 5.8 | K4: 2.5 | L4: =$E$5*F4 -> 6.5 | M4: =$E$4*G4 -> 5.2 | N4: =$E$4*H4 -> 2.8 | O4: =$E$6*I4 -> 2.5 | P4: =$E$6*J4 -> 5.8 | Q4: =$E$4*K4 -> 2.5
A5: 3 | B5: Extraversion | C5: 1 | D5: 0 | E5: =C5*(1+D5) -> 1 | F5: 4.6 | G5: 6.5 | H5: 2.8 | I5: 5.5 | J5: 3 | K5: 2 | L5: =$E$5*F5 -> 4.6 | M5: =$E$4*G5 -> 6.5 | N5: =$E$4*H5 -> 2.8 | O5: =$E$6*I5 -> 5.5 | P5: =$E$6*J5 -> 3 | Q5: =$E$4*K5 -> 2
A6: 4 | B6: Agreeableness | C6: 1 | D6: 0 | E6: =C6*(1+D6) -> 1 | F6: 5.5 | G6: 6 | H6: 5 | I6: 4 | J6: 5 | K6: 4 | L6: =$E$5*F6 -> 5.5 | M6: =$E$4*G6 -> 6 | N6: =$E$4*H6 -> 5 | O6: =$E$6*I6 -> 4 | P6: =$E$6*J6 -> 5 | Q6: =$E$4*K6 -> 4
A7: 5 | B7: Neuroticism | C7: 1 | D7: 0 | E7: =C7*(1+D7) -> 1 | F7: 1.5 | G7: 2.8 | H7: 6 | I7: 2.5 | J7: 2 | K7: 6.5 | L7: =$E$5*F7 -> 1.5 | M7: =$E$4*G7 -> 2.8 | N7: =$E$4*H7 -> 6 | O7: =$E$6*I7 -> 2.5 | P7: =$E$6*J7 -> 2 | Q7: =$E$4*K7 -> 6.5
F10: 3
F11: 2.92
F12: 3.12
F13: 2.79
F14: 5.17

Sheet Tech plan
A2: 1 | B2: Simple landing page | C2: Page with information about the tool
A3: 2 | B3: User registration | C3: Email ID
A4: 3 | B4: Login | C4: Native login + Social media login (Google, FB, Linkedin)
A5: 4 | B5: Assessment questions (scroll mode) | C5: Auto-scrolling. Cant go to next question if current one unanswered.
A6: 5 | B6: Auto save feature | C6: All responses must be saved and assessment can be continued later
A7: 6 | B7: Summary Results page | F7: Pricing
A8: 7 | B8: Share results option | C8: Should be shareable to Insta, FB, Twitter, Linkedin | F8: Examples web app
A9: 8 | B9: Email/Whatsapp detailed report | C9: PDF format sent on mail/whatsapp
A10: 9 | B10: Gift assessment | C10: Mail, whatsapp
A11: 10 | B11: Payment gateway | C11: Payment with voucher option
A12: 11 | B12: Responsive pages
A13: 12 | B13: High speed and effects
A14: 13 | B14: Great UI/UX
A15: 14 | B15: Database | C15: Multi-table database
A16: 15 | B16: Report extraction | C16: Data reporting layer - User table/Responses table/Persona table
A17: 16 | B17: Admin page | C17: Facility to change centroids, weights, etc.
A18: 17 | B18: Country recognition | C18: Currency must change depending on India vs other geographies. INR vs USD
A19: 18 | B19: Business Cpanel | C19: Send assessment links Store assessment results
